Workbook
Name Slicer_Category: #N/A
Name Slicer_Region: #N/A

Sheet New Dashboard
A1: E -Commerce Sales DataSet
K3: How they like to buy

Sheet PIVOTS
A3: Sum of Total_Amount | B3: Column Labels
A4: Row Labels | B4: East | C4: North | D4: South | E4: West | F4: Grand Total
A5: Beauty | B5: 93738.074 | C5: 90887.545 | D5: 101876.16 | E5: 35059.548 | F5: 321561.33 | O5: Sum of Total_Amount | P5: . | U5: =P6 -> Female | V5: =Q6 -> Male
A6: Clothing | B6: 105166.69 | C6: 111832.22 | D6: 113264.13 | E6: 48953.004 | F6: 379216.04 | O6: Row Labels | P6: Female | Q6: Male | R6: Grand Total | T6: =O7 -> Flagship | U6: =P7 -> 0.21581193 | V6: =Q7 -> 0.17444687
A7: Electronics | B7: 133221.68 | C7: 147510.96 | D7: 147714.64 | E7: 75864.076 | F7: 504311.35 | O7: Flagship | P7: 0.21581193 | Q7: 0.17444687 | R7: 0.3902588 | T7: =O8 -> Online | U7: =P8 -> 0.24160718 | V7: =Q8 -> 0.17885628
A8: Home | B8: 120153.86 | C8: 129789.2 | D8: 117057.06 | E8: 60295.68 | F8: 427295.8 | O8: Online | P8: 0.24160718 | Q8: 0.17885628 | R8: 0.42046346 | T8: =O9 -> Outlet | U8: =P9 -> 0.10891976 | V8: =Q9 -> 0.080357978
A9: Sports | B9: 170124.02 | C9: 166080.96 | D9: 155301.1 | E9: 50504.098 | F9: 542010.17 | O9: Outlet | P9: 0.10891976 | Q9: 0.080357978 | R9: 0.18927774
A10: Grand Total | B10: 622404.32 | C10: 646100.88 | D10: 635213.1 | E10: 270676.41 | F10: 2174394.7 | O10: Grand Total | P10: 0.56633887 | Q10: 0.43366113 | R10: 1
B15: Count of Sales_ID | C15: Column Labels | O15: Row Labels | P15: Sum of Quantity
B16: Row Labels | C16: Flagship | D16: Online | E16: Outlet | F16: Grand Total | O16: CUST1054 | P16: 30
B17: COD | C17: 288 | D17: 254 | E17: 118 | F17: 660 | O17: CUST1219 | P17: 29
B18: Credit Card | C18: 243 | D18: 269 | E18: 133 | F18: 645 | O18: CUST1108 | P18: 27
B19: PayPal | C19: 263 | D19: 299 | E19: 133 | F19: 695 | I19: Row Labels | J19: Sum of Total_Amount | O19: CUST1084 | P19: 27
B20: Grand Total | C20: 794 | D20: 822 | E20: 384 | F20: 2000 | I20: 2023 | J20: 223812.72 | O20: CUST1470 | P20: 25 | W20: Sum of Quantity | X20: Column Labels | AC20: Row Labels | AD20: Sum of Quantity | AE20: Sum of Total_Amount
I21: Qtr4 | J21: 223812.72 | L21: Row Labels | M21: Sum of Total_Amount | O21: CUST1051 | P21: 25 | W21: Row Labels | X21: Female | Y21: Male | Z21: Grand Total | AC21: Alabama | AD21: 105 | AE21: 49377.684 | AH21: USA | AI21: =AC21 -> Alabama | AJ21: =AD21 -> 105
I22: 2024 | J22: 1093911.8 | L22: 2023 | M22: 223812.72 | O22: CUST1168 | P22: 25 | W22: Sports | X22: 714 | Y22: 527 | Z22: 1241 | AC22: Alaska | AD22: 103 | AE22: 49032.414 | AH22: USA | AI22: =AC22 -> Alaska | AJ22: =AD22 -> 103
C23: Column Labels | I23: Qtr1 | J23: 268596.98 | L23: 2024 | M23: 1093911.8 | O23: CUST1007 | P23: 25 | W23: Electronics | X23: 657 | Y23: 508 | Z23: 1165 | AC23: Arizona | AD23: 101 | AE23: 46317.776 | AH23: USA | AI23: =AC23 -> Arizona | AJ23: =AD23 -> 101
C24: East | D24: North | E24: South | F24: West | G24: Grand Total | I24: Qtr2 | J24: 245299.96 | L24: 2025 | M24: 856670.18 | O24: CUST1013 | P24: 24 | W24: Home | X24: 514 | Y24: 460 | Z24: 974 | AC24: Arkansas | AD24: 61 | AE24: 24828.745 | AH24: USA | AI24: =AC24 -> Arkansas | AJ24: =AD24 -> 61
B25: Sum of Total_Amount | C25: 622404.32 | D25: 646100.88 | E25: 635213.1 | F25: 270676.41 | G25: 2174394.7 | I25: Qtr3 | J25: 285586.04 | L25: Grand Total | M25: 2174394.7 | O25: CUST1371 | P25: 24 | W25: Clothing | X25: 483 | Y25: 363 | Z25: 846 | AC25: California | AD25: 124 | AE25: 47072.305 | AH25: USA | AI25: =AC25 -> California | AJ25: =AD25 -> 124
I26: Qtr4 | J26: 294428.82 | O26: CUST1057 | P26: 24 | W26: Beauty | X26: 404 | Y26: 334 | Z26: 738 | AC26: Colorado | AD26: 21 | AE26: 9312.2465 | AH26: USA | AI26: =AC26 -> Colorado | AJ26: =AD26 -> 21
I27: 2025 | J27: 856670.18 | O27: CUST1067 | P27: 23 | W27: Grand Total | X27: 2772 | Y27: 2192 | Z27: 4964 | AC27: Connecticut | AD27: 142 | AE27: 56723.038 | AH27: USA | AI27: =AC27 -> Connecticut | AJ27: =AD27 -> 142
I28: Qtr1 | J28: 271630.62 | O28: CUST1373 | P28: 22 | AC28: Delaware | AD28: 84 | AE28: 29967.98 | AH28: USA | AI28: =AC28 -> Delaware | AJ28: =AD28 -> 84
I29: Qtr2 | J29: 256716.06 | O29: CUST1348 | P29: 22 | AC29: Florida | AD29: 127 | AE29: 60406.676 | AH29: USA | AI29: =AC29 -> Florida | AJ29: =AD29 -> 127
I30: Qtr3 | J30: 289855.68 | O30: CUST1485 | P30: 22 | AC30: Georgia | AD30: 123 | AE30: 47224.799 | AH30: USA | AI30: =AC30 -> Georgia | AJ30: =AD30 -> 123
I31: Qtr4 | J31: 38467.816 | O31: CUST1147 | P31: 21 | AC31: Hawaii | AD31: 75 | AE31: 34436.901 | AH31: USA | AI31: =AC31 -> Hawaii | AJ31: =AD31 -> 75
I32: Grand Total | J32: 2174394.7 | O32: CUST1466 | P32: 21 | AC32: Idaho | AD32: 25 | AE32: 12801.172 | AH32: USA | AI32: =AC32 -> Idaho | AJ32: =AD32 -> 25
O33: CUST1052 | P33: 20 | AC33: Illinois | AD33: 74 | AE33: 32348.639 | AH33: USA | AI33: =AC33 -> Illinois | AJ33: =AD33 -> 74
O34: CUST1101 | P34: 20 | AC34: Indiana | AD34: 108 | AE34: 51827.029 | AH34: USA | AI34: =AC34 -> Indiana | AJ34: =AD34 -> 108
O35: CUST1478 | P35: 19 | AC35: Iowa | AD35: 126 | AE35: 51613.308 | AH35: USA | AI35: =AC35 -> Iowa | AJ35: =AD35 -> 126
O36: CUST1251 | P36: 19 | AC36: Kansas | AD36: 124 | AE36: 58787.176 | AH36: USA | AI36: =AC36 -> Kansas | AJ36: =AD36 -> 124
O37: CUST1156 | P37: 19 | AC37: Kentucky | AD37: 60 | AE37: 23445.226 | AH37: USA | AI37: =AC37 -> Kentucky | AJ37: =AD37 -> 60
O38: CUST1462 | P38: 19 | AC38: Louisiana | AD38: 97 | AE38: 41264.121 | AH38: USA | AI38: =AC38 -> Louisiana | AJ38: =AD38 -> 97
O39: CUST1104 | P39: 19 | AC39: Maine | AD39: 92 | AE39: 43827.302 | AH39: USA | AI39: =AC39 -> Maine | AJ39: =AD39 -> 92
O40: CUST1039 | P40: 19 | AC40: Maryland | AD40: 75 | AE40: 27871.036 | AH40: USA | AI40: =AC40 -> Maryland | AJ40: =AD40 -> 75
O41: CUST1209 | P41: 19 | AC41: Massachusetts | AD41: 55 | AE41: 26107.866 | AH41: USA | AI41: =AC41 -> Massachusetts | AJ41: =AD41 -> 55
O42: CUST1248 | P42: 19 | AC42: Michigan | AD42: 109 | AE42: 44872.697 | AH42: USA | AI42: =AC42 -> Michigan | AJ42: =AD42 -> 109
O43: CUST1384 | P43: 18 | AC43: Minnesota | AD43: 106 | AE43: 47628.872 | AH43: USA | AI43: =AC43 -> Minnesota | AJ43: =AD43 -> 106
O44: CUST1072 | P44: 18 | AC44: Mississippi | AD44: 51 | AE44: 30570.603 | AH44: USA | AI44: =AC44 -> Mississippi | AJ44: =AD44 -> 51
... O70: CUST1164 | P70: 17 | AC70: Wyoming | AD70: 47 | AE70: 17815.739 | AH70: USA | AI70: =AC70 -> Wyoming | AJ70: =AD70 -> 47
O71: CUST1343 | P71: 17 | AC71: Grand Total | AD71: 4964 | AE71: 2174394.7
...

Sheet Summary
A1: INSIGHTS
A3: 1 | B3: This assignment focuses on analyzing an Ecommerce dataset using Microsoft Excel. The dataset was imported into Excel and organized into structured tables for efficient analysis. Multiple sheets were used to clearly separate raw data, cleaned data, pivot tables, and dashboard elements.
A7: 2 | B7: Data cleaning was performed to ensure accuracy and consistency
A8: 3 | B8: Duplicate records were identified and removed, missing values were handled appropriately, and formatting issues such as date and numeric inconsistencies were corrected. Data validation techniques were applied to maintain data quality.
A9: 4 | B9: Excel formulas such as SUM, SUMIF, COUNTIF, AVERAGE, TEXT, and
A10: 5 | B10: VLOOKUP were used to combine data from multiple tables. VLOOKUP was used to link related datasets
A11: 6 | B11: Descriptive statistics including mean, median, and standard deviation were calculated using Analysis ToolPak,
A12: 7 | B12: Pivot Tables were created to summarize data across multiple dimensions such as category, product and region
A13: 8 | B13: Pivot Tables formed the foundation for analysis and dashboard visuals.
A14: 9 | B14: An interactive dashboard was built using Column, Bar, and Pie charts along with PivotCharts and slicers. Key Performance Indicators (KPIs) such as Total Sales, Total Orders, Average Order Value, highlighted at the side of the dashboard for quick insights
A15: 10 | B15: Key findings show that certain product categories contribute significantly more to overall revenue, while a few top products drive the majority of sales. Monthly sales trends reveal seasonal patterns, and regional analysis highlights high-performing locations. Overall, this analysis provides meaningful insights into sales performance, customer behavior, and product contribution using Excel tools.

Sheet Sales_Fact (3)
A1: Sales_ID | B1: Customer Name | C1: City | D1: Age | E1: Sex | F1: State | G1: Loyalty_level | H1: Customer_ID | I1: Order date | J1: Product_ID | K1: Category | L1: Sub_Category | M1: Product Cost | N1: Stock | O1: Store_ID | P1: StoreName | Q1: Region | R1: Store city | S1: Store Type | T1: Quantity | U1: Unit_Price | V1: Discount | W1: Payment_Type | X1: Total_Amount
A2: SALE0 | B2: =VLOOKUP(Table6[[#This Row],[Customer_ID]],Table1[[Customer_ID]:[Name]],2,FALSE) -> Sarah Smith | C2: =VLOOKUP(Table6[[#This Row],[Customer_ID]],Table1[[Customer_ID]:[City]],5,FALSE) -> Kathleenport | D2: =VLOOKUP(Table6[[#This Row],[Customer_ID]],Table1[],3,FALSE) -> 55 | E2: =VLOOKUP(Table6[[#This Row],[Customer_ID]],Table1[],4,FALSE) -> Male | F2: =VLOOKUP(Table6[[#This Row],[Customer_ID]],Table1[],6,FALSE) -> Wyoming | G2: =VLOOKUP(Table6[[#This Row],[Customer_ID]],Table1[],8,FALSE) -> Gold | H2: CUST1409 | I2: 45480 | J2: PROD97 | K2: =VLOOKUP($J2,'Product_Dim (2)'!$A$2:$G$101,{3,4,5,6},FALSE) -> Sports | L2: =VLOOKUP($J2,'Product_Dim (2)'!$A$2:$G$101,{4,5,6},FALSE) -> Team Sports | M2: {=VLOOKUP($J2,'Product_Dim (2)'!$A$2:$G$101,{6},FALSE)} -> 245.98 | N2: =VLOOKUP($J2,'Product_Dim (2)'!$A$2:$G$101,7,FALSE) -> 471 | O2: STORE3 | P2: =VLOOKUP($O2,'Store_Dim (2)'!$A$2:$E$21,2,FALSE) -> Johnson-Wright | Q2: =VLOOKUP(Table6[[#This Row],[Store_ID]],Table4[],3,FALSE) -> North | R2: =VLOOKUP(Table6[[#This Row],[Store_ID]],Table4[],4,FALSE) -> Hoodberg | S2: =VLOOKUP(Table6[[#This Row],[Store_ID]],Table4[],5,FALSE) -> Outlet | T2: 1 | U2: 218.04 | V2: 0.09 | W2: Credit Card | X2: 198.4164
A3: SALE1 | B3: =VLOOKUP(Table6[[#This Row],[Customer_ID]],Table1[[Customer_ID]:[Name]],2,FALSE) -> Michael Foley | C3: =VLOOKUP(Table6[[#This Row],[Customer_ID]],Table1[[Customer_ID]:[City]],5,FALSE) -> Oneillfurt | D3: =VLOOKUP(Table6[[#This Row],[Customer_ID]],Table1[],3,FALSE) -> 63 | E3: =VLOOKUP(Table6[[#This Row],[Customer_ID]],Table1[],4,FALSE) -> Female | F3: =VLOOKUP(Table6[[#This Row],[Customer_ID]],Table1[],6,FALSE) -> Vermont | G3: =VLOOKUP(Table6[[#This Row],[Customer_ID]],Table1[],8,FALSE) -> Gold | H3: CUST1467 | I3: 45285 | J3: PROD74 | K3: =VLOOKUP($J3,'Product_Dim (2)'!$A$2:$G$101,{3,4,5,6},FALSE) -> Electronics | L3: =VLOOKUP($J3,'Product_Dim (2)'!$A$2:$G$101,{4,5,6},FALSE) -> Audio | M3: {=VLOOKUP($J3,'Product_Dim (2)'!$A$2:$G$101,{6},FALSE)} -> 403.71 | N3: =VLOOKUP($J3,'Product_Dim (2)'!$A$2:$G$101,7,FALSE) -> 159 | O3: STORE17 | P3: =VLOOKUP($O3,'Store_Dim (2)'!$A$2:$E$21,2,FALSE) -> Holloway Ltd | Q3: =VLOOKUP(Table6[[#This Row],[Store_ID]],Table4[],3,FALSE) -> North | R3: =VLOOKUP(Table6[[#This Row],[Store_ID]],Table4[],4,FALSE) -> Bensonhaven | S3: =VLOOKUP(Table6[[#This Row],[Store_ID]],Table4[],5,FALSE) -> Flagship | T3: 3 | U3: 104.47 | V3: 0.27 | W3: PayPal | X3: 228.7893
A4: SALE2 | B4: =VLOOKUP(Table6[[#This Row],[Customer_ID]],Table1[[Customer_ID]:[Name]],2,FALSE) -> Christopher Sutton | C4: =VLOOKUP(Table6[[#This Row],[Customer_ID]],Table1[[Customer_ID]:[City]],5,FALSE) -> Deborahberg | D4: =VLOOKUP(Table6[[#This Row],[Customer_ID]],Table1[],3,FALSE) -> 49 | E4: =VLOOKUP(Table6[[#This Row],[Customer_ID]],Table1[],4,FALSE) -> Female | F4: =VLOOKUP(Table6[[#This Row],[Customer_ID]],Table1[],6,FALSE) -> Pennsylvania | G4: =VLOOKUP(Table6[[#This Row],[Customer_ID]],Table1[],8,FALSE) -> Gold | H4: CUST1056 | I4: 45446 | J4: PROD49 | K4: =VLOOKUP($J4,'Product_Dim (2)'!$A$2:$G$101,{3,4,5,6},FALSE) -> Beauty | L4: =VLOOKUP($J4,'Product_Dim (2)'!$A$2:$G$101,{4,5,6},FALSE) -> Fragrance | M4: {=VLOOKUP($J4,'Product_Dim (2)'!$A$2:$G$101,{6},FALSE)} -> 43.29 | N4: =VLOOKUP($J4,'Product_Dim (2)'!$A$2:$G$101,7,FALSE) -> 267 | O4: STORE8 | P4: =VLOOKUP($O4,'Store_Dim (2)'!$A$2:$E$21,2,FALSE) -> Bean, Jones and Park | Q4: =VLOOKUP(Table6[[#This Row],[Store_ID]],Table4[],3,FALSE) -> West | R4: =VLOOKUP(Table6[[#This Row],[Store_ID]],Table4[],4,FALSE) -> Thompsonborough | S4: =VLOOKUP(Table6[[#This Row],[Store_ID]],Table4[],5,FALSE) -> Online | T4: 4 | U4: 914.05 | V4: 0.25 | W4: Credit Card | X4: 2742.15
A5: SALE3 | B5: =VLOOKUP(Table6[[#This Row],[Customer_ID]],Table1[[Customer_ID]:[Name]],2,FALSE) -> John Jordan | C5: =VLOOKUP(Table6[[#This Row],[Customer_ID]],Table1[[Customer_ID]:[City]],5,FALSE) -> Port Crystalberg | D5: =VLOOKUP(Table6[[#This Row],[Customer_ID]],Table1[],3,FALSE) -> 58 | E5: =VLOOKUP(Table6[[#This Row],[Customer_ID]],Table1[],4,FALSE) -> Female | F5: =VLOOKUP(Table6[[#This Row],[Customer_ID]],Table1[],6,FALSE) -> Tennessee | G5: =VLOOKUP(Table6[[#This Row],[Customer_ID]],Table1[],8,FALSE) -> Platinum | H5: CUST1346 | I5: 45259 | J5: PROD76 | K5: =VLOOKUP($J5,'Product_Dim (2)'!$A$2:$G$101,{3,4,5,6},FALSE) -> Electronics | L5: =VLOOKUP($J5,'Product_Dim (2)'!$A$2:$G$101,{4,5,6},FALSE) -> Computer | M5: {=VLOOKUP($J5,'Product_Dim (2)'!$A$2:$G$101,{6},FALSE)} -> 392.89 | N5: =VLOOKUP($J5,'Product_Dim (2)'!$A$2:$G$101,7,FALSE) -> 320 | O5: STORE8 | P5: =VLOOKUP($O5,'Store_Dim (2)'!$A$2:$E$21,2,FALSE) -> Bean, Jones and Park | Q5: =VLOOKUP(Table6[[#This Row],[Store_ID]],Table4[],3,FALSE) -> West | R5: =VLOOKUP(Table6[[#This Row],[Store_ID]],Table4[],4,FALSE) -> Thompsonborough | S5: =VLOOKUP(Table6[[#This Row],[Store_ID]],Table4[],5,FALSE) -> Online | T5: 1 | U5: 921.51 | V5: 0.16 | W5: COD | X5: 774.0684
A6: SALE4 | B6: =VLOOKUP(Table6[[#This Row],[Customer_ID]],Table1[[Customer_ID]:[Name]],2,FALSE) -> Amanda Powell | C6: =VLOOKUP(Table6[[#This Row],[Customer_ID]],Table1[[Customer_ID]:[City]],5,FALSE) -> South William | D6: =VLOOKUP(Table6[[#This Row],[Customer_ID]],Table1[],3,FALSE) -> 28 | E6: =VLOOKUP(Table6[[#This Row],[Customer_ID]],Table1[],4,FALSE) -> Male | F6: =VLOOKUP(Table6[[#This Row],[Customer_ID]],Table1[],6,FALSE) -> Alabama | G6: =VLOOKUP(Table6[[#This Row],[Customer_ID]],Table1[],8,FALSE) -> Silver | H6: CUST1493 | I6: 45297 | J6: PROD59 | K6: =VLOOKUP($J6,'Product_Dim (2)'!$A$2:$G$101,{3,4,5,6},FALSE) -> Beauty | L6: =VLOOKUP($J6,'Product_Dim (2)'!$A$2:$G$101,{4,5,6},FALSE) -> Haircare | M6: {=VLOOKUP($J6,'Product_Dim (2)'!$A$2:$G$101,{6},FALSE)} -> 17.31 | N6: =VLOOKUP($J6,'Product_Dim (2)'!$A$2:$G$101,7,FALSE) -> 399 | O6: STORE5 | P6: =VLOOKUP($O6,'Store_Dim (2)'!$A$2:$E$21,2,FALSE) -> Gray Ltd | Q6: =VLOOKUP(Table6[[#This Row],[Store_ID]],Table4[],3,FALSE) -> North | R6: =VLOOKUP(Table6[[#This Row],[Store_ID]],Table4[],4,FALSE) -> New Michaelchester | S6: =VLOOKUP(Table6[[#This Row],[Store_ID]],Table4[],5,FALSE) -> Outlet | T6: 3 | U6: 745.3 | V6: 0.18 | W6: Credit Card | X6: 1833.438
A7: SALE5 | B7: =VLOOKUP(Table6[[#This Row],[Customer_ID]],Table1[[Customer_ID]:[Name]],2,FALSE) -> Anthony Phillips | C7: =VLOOKUP(Table6[[#This Row],[Customer_ID]],Table1[[Customer_ID]:[City]],5,FALSE) -> North Davidport | D7: =VLOOKUP(Table6[[#This Row],[Customer_ID]],Table1[],3,FALSE) -> 18 | E7: =VLOOKUP(Table6[[#This Row],[Customer_ID]],Table1[],4,FALSE) -> Female | F7: =VLOOKUP(Table6[[#This Row],[Customer_ID]],Table1[],6,FALSE) -> Rhode Island | G7: =VLOOKUP(Table6[[#This Row],[Customer_ID]],Table1[],8,FALSE) -> Platinum | H7: CUST1116 | I7: 45499 | J7: PROD15 | K7: =VLOOKUP($J7,'Product_Dim (2)'!$A$2:$G$101,{3,4,5,6},FALSE) -> Electronics | L7: =VLOOKUP($J7,'Product_Dim (2)'!$A$2:$G$101,{4,5,6},FALSE) -> Appliances | M7: {=VLOOKUP($J7,'Product_Dim (2)'!$A$2:$G$101,{6},FALSE)} -> 465.34 | N7: =VLOOKUP($J7,'Product_Dim (2)'!$A$2:$G$101,7,FALSE) -> 301 | O7: STORE7 | P7: =VLOOKUP($O7,'Store_Dim (2)'!$A$2:$E$21,2,FALSE) -> Martinez-Mullins | Q7: =VLOOKUP(Table6[[#This Row],[Store_ID]],Table4[],3,FALSE) -> South | R7: =VLOOKUP(Table6[[#This Row],[Store_ID]],Table4[],4,FALSE) -> Williamsfurt | S7: =VLOOKUP(Table6[[#This Row],[Store_ID]],Table4[],5,FALSE) -> Online | T7: 3 | U7: 147.01 | V7: 0.19 | W7: COD | X7: 357.2343
A8: SALE6 | B8: =VLOOKUP(Table6[[#This Row],[Customer_ID]],Table1[[Customer_ID]:[Name]],2,FALSE) -> John Scott | C8: =VLOOKUP(Table6[[#This Row],[Customer_ID]],Table1[[Customer_ID]:[City]],5,FALSE) -> South Christopher | D8: =VLOOKUP(Table6[[#This Row],[Customer_ID]],Table1[],3,FALSE) -> 24 | E8: =VLOOKUP(Table6[[#This Row],[Customer_ID]],Table1[],4,FALSE) -> Female | F8: =VLOOKUP(Table6[[#This Row],[Customer_ID]],Table1[],6,FALSE) -> Pennsylvania | G8: =VLOOKUP(Table6[[#This Row],[Customer_ID]],Table1[],8,FALSE) -> Bronze | H8: CUST1016 | I8: 45850 | J8: PROD56 | K8: =VLOOKUP($J8,'Product_Dim (2)'!$A$2:$G$101,{3,4,5,6},FALSE) -> Home | L8: =VLOOKUP($J8,'Product_Dim (2)'!$A$2:$G$101,{4,5,6},FALSE) -> Decor | M8: {=VLOOKUP($J8,'Product_Dim (2)'!$A$2:$G$101,{6},FALSE)} -> 461.47 | N8: =VLOOKUP($J8,'Product_Dim (2)'!$A$2:$G$101,7,FALSE) -> 190 | O8: STORE4 | P8: =VLOOKUP($O8,'Store_Dim (2)'!$A$2:$E$21,2,FALSE) -> Alexander Group | Q8: =VLOOKUP(Table6[[#This Row],[Store_ID]],Table4[],3,FALSE) -> South | R8: =VLOOKUP(Table6[[#This Row],[Store_ID]],Table4[],4,FALSE) -> Port Sharon | S8: =VLOOKUP(Table6[[#This Row],[Store_ID]],Table4[],5,FALSE) -> Online | T8: 2 | U8: 785.31 | V8: 0.15 | W8: PayPal | X8: 1335.027
A9: SALE7 | B9: =VLOOKUP(Table6[[#This Row],[Customer_ID]],Table1[[Customer_ID]:[Name]],2,FALSE) -> Patrick Roberts | C9: =VLOOKUP(Table6[[#This Row],[Customer_ID]],Table1[[Customer_ID]:[City]],5,FALSE) -> Jaredville | D9: =VLOOKUP(Table6[[#This Row],[Customer_ID]],Table1[],3,FALSE) -> 41 | E9: =VLOOKUP(Table6[[#This Row],[Customer_ID]],Table1[],4,FALSE) -> Female | F9: =VLOOKUP(Table6[[#This Row],[Customer_ID]],Table1[],6,FALSE) -> Missouri | G9: =VLOOKUP(Table6[[#This Row],[Customer_ID]],Table1[],8,FALSE) -> Platinum | H9: CUST1152 | I9: 45248 | J9: PROD70 | K9: =VLOOKUP($J9,'Product_Dim (2)'!$A$2:$G$101,{3,4,5,6},FALSE) -> Home | L9: =VLOOKUP($J9,'Product_Dim (2)'!$A$2:$G$101,{4,5,6},FALSE) -> Storage | M9: {=VLOOKUP($J9,'Product_Dim (2)'!$A$2:$G$101,{6},FALSE)} -> 138.05 | N9: =VLOOKUP($J9,'Product_Dim (2)'!$A$2:$G$101,7,FALSE) -> 89 | O9: STORE8 | P9: =VLOOKUP($O9,'Store_Dim (2)'!$A$2:$E$21,2,FALSE) -> Bean, Jones and Park | Q9: =VLOOKUP(Table6[[#This Row],[Store_ID]],Table4[],3,FALSE) -> West | R9: =VLOOKUP(Table6[[#This Row],[Store_ID]],Table4[],4,FALSE) -> Thompsonborough | S9: =VLOOKUP(Table6[[#This Row],[Store_ID]],Table4[],5,FALSE) -> Online | T9: 4 | U9: 342.39 | V9: 0.23 | W9: PayPal | X9: 1054.5612
A10: SALE8 | B10: =VLOOKUP(Table6[[#This Row],[Customer_ID]],Table1[[Customer_ID]:[Name]],2,FALSE) -> Dr. Suzanne Bullock | C10: =VLOOKUP(Table6[[#This Row],[Customer_ID]],Table1[[Customer_ID]:[City]],5,FALSE) -> Lake Blaketon | D10: =VLOOKUP(Table6[[#This Row],[Customer_ID]],Table1[],3,FALSE) -> 60 | E10: =VLOOKUP(Table6[[#This Row],[Customer_ID]],Table1[],4,FALSE) -> Female | F10: =VLOOKUP(Table6[[#This Row],[Customer_ID]],Table1[],6,FALSE) -> Alabama | G10: =VLOOKUP(Table6[[#This Row],[Customer_ID]],Table1[],8,FALSE) -> Platinum | H10: CUST1187 | I10: 45781 | J10: PROD99 | K10: =VLOOKUP($J10,'Product_Dim (2)'!$A$2:$G$101,{3,4,5,6},FALSE) -> Home | L10: =VLOOKUP($J10,'Product_Dim (2)'!$A$2:$G$101,{4,5,6},FALSE) -> Kitchen | M10: {=VLOOKUP($J10,'Product_Dim (2)'!$A$2:$G$101,{6},FALSE)} -> 201.41 | N10: =VLOOKUP($J10,'Product_Dim (2)'!$A$2:$G$101,7,FALSE) -> 146 | O10: STORE5 | P10: =VLOOKUP($O10,'Store_Dim (2)'!$A$2:$E$21,2,FALSE) -> Gray Ltd | Q10: =VLOOKUP(Table6[[#This Row],[Store_ID]],Table4[],3,FALSE) -> North | R10: =VLOOKUP(Table6[[#This Row],[Store_ID]],Table4[],4,FALSE) -> New Michaelchester | S10: =VLOOKUP(Table6[[#This Row],[Store_ID]],Table4[],5,FALSE) -> Outlet | T10: =X10/(U10*(1-V10)) -> 3 | U10: 448.25 | V10: 0.07 | W10: PayPal | X10: 1250.6175
A11: SALE9 | B11: =VLOOKUP(Table6[[#This Row],[Customer_ID]],Table1[[Customer_ID]:[Name]],2,FALSE) -> David Pierce | C11: =VLOOKUP(Table6[[#This Row],[Customer_ID]],Table1[[Customer_ID]:[City]],5,FALSE) -> Grayland | D11: =VLOOKUP(Table6[[#This Row],[Customer_ID]],Table1[],3,FALSE) -> 45 | E11: =VLOOKUP(Table6[[#This Row],[Customer_ID]],Table1[],4,FALSE) -> Female | F11: =VLOOKUP(Table6[[#This Row],[Customer_ID]],Table1[],6,FALSE) -> Washington | G11: =VLOOKUP(Table6[[#This Row],[Customer_ID]],Table1[],8,FALSE) -> Platinum | H11: CUST1464 | I11: 45869 | J11: PROD33 | K11: =VLOOKUP($J11,'Product_Dim (2)'!$A$2:$G$101,{3,4,5,6},FALSE) -> Home | L11: =VLOOKUP($J11,'Product_Dim (2)'!$A$2:$G$101,{4,5,6},FALSE) -> Decor | M11: {=VLOOKUP($J11,'Product_Dim (2)'!$A$2:$G$101,{6},FALSE)} -> 179.77 | N11: =VLOOKUP($J11,'Product_Dim (2)'!$A$2:$G$101,7,FALSE) -> 305 | O11: STORE0 | P11: =VLOOKUP($O11,'Store_Dim (2)'!$A$2:$E$21,2,FALSE) -> Rivera-Warner | Q11: =VLOOKUP(Table6[[#This Row],[Store_ID]],Table4[],3,FALSE) -> East | R11: =VLOOKUP(Table6[[#This Row],[Store_ID]],Table4[],4,FALSE) -> Washingtonfurt | S11: =VLOOKUP(Table6[[#This Row],[Store_ID]],Table4[],5,FALSE) -> Flagship | T11: 2 | U11: 873.17 | V11: 0.23 | W11: PayPal | X11: 1344.6818
A12: SALE10 | B12: =VLOOKUP(Table6[[#This Row],[Customer_ID]],Table1[[Customer_ID]:[Name]],2,FALSE) -> Michael Thomas | C12: =VLOOKUP(Table6[[#This Row],[Customer_ID]],Table1[[Customer_ID]:[City]],5,FALSE) -> Woodmouth | D12: =VLOOKUP(Table6[[#This Row],[Customer_ID]],Table1[],3,FALSE) -> 21 | E12: =VLOOKUP(Table6[[#This Row],[Customer_ID]],Table1[],4,FALSE) -> Female | F12: =VLOOKUP(Table6[[#This Row],[Customer_ID]],Table1[],6,FALSE) -> Nevada | G12: =VLOOKUP(Table6[[#This Row],[Customer_ID]],Table1[],8,FALSE) -> Silver | H12: CUST1065 | I12: 45335 | J12: PROD24 | K12: =VLOOKUP($J12,'Product_Dim (2)'!$A$2:$G$101,{3,4,5,6},FALSE) -> Sports | L12: =VLOOKUP($J12,'Product_Dim (2)'!$A$2:$G$101,{4,5,6},FALSE) -> Outdoor | M12: {=VLOOKUP($J12,'Product_Dim (2)'!$A$2:$G$101,{6},FALSE)} -> 166.06 | N12: =VLOOKUP($J12,'Product_Dim (2)'!$A$2:$G$101,7,FALSE) -> 340 | O12: STORE14 | P12: =VLOOKUP($O12,'Store_Dim (2)'!$A$2:$E$21,2,FALSE) -> Mcdonald Inc | Q12: =VLOOKUP(Table6[[#This Row],[Store_ID]],Table4[],3,FALSE) -> South | R12: =VLOOKUP(Table6[[#This Row],[Store_ID]],Table4[],4,FALSE) -> Christopherland | S12: =VLOOKUP(Table6[[#This Row],[Store_ID]],Table4[],5,FALSE) -> Outlet | T12: 1 | U12: 278.63 | V12: 0.07 | W12: Credit Card | X12: 259.1259
A13: SALE11 | B13: =VLOOKUP(Table6[[#This Row],[Customer_ID]],Table1[[Customer_ID]:[Name]],2,FALSE) -> Jessica Gonzalez | C13: =VLOOKUP(Table6[[#This Row],[Customer_ID]],Table1[[Customer_ID]:[City]],5,FALSE) -> South Darrenland | D13: =VLOOKUP(Table6[[#This Row],[Customer_ID]],Table1[],3,FALSE) -> 34 | E13: =VLOOKUP(Table6[[#This Row],[Customer_ID]],Table1[],4,FALSE) -> Female | F13: =VLOOKUP(Table6[[#This Row],[Customer_ID]],Table1[],6,FALSE) -> Iowa | G13: =VLOOKUP(Table6[[#This Row],[Customer_ID]],Table1[],8,FALSE) -> Bronze | H13: CUST1320 | I13: 45801 | J13: PROD39 | K13: =VLOOKUP($J13,'Product_Dim (2)'!$A$2:$G$101,{3,4,5,6},FALSE) -> Electronics | L13: =VLOOKUP($J13,'Product_Dim (2)'!$A$2:$G$101,{4,5,6},FALSE) -> Mobile | M13: {=VLOOKUP($J13,'Product_Dim (2)'!$A$2:$G$101,{6},FALSE)} -> 326.06 | N13: =VLOOKUP($J13,'Product_Dim (2)'!$A$2:$G$101,7,FALSE) -> 301 | O13: STORE1 | P13: =VLOOKUP($O13,'Store_Dim (2)'!$A$2:$E$21,2,FALSE) -> Martinez, Adkins and Johnson | Q13: =VLOOKUP(Table6[[#This Row],[Store_ID]],Table4[],3,FALSE) -> North | R13: =VLOOKUP(Table6[[#This Row],[Store_ID]],Table4[],4,FALSE) -> Danielmouth | S13: =VLOOKUP(Table6[[#This Row],[Store_ID]],Table4[],5,FALSE) -> Flagship | T13: 4 | U13: 286.92 | V13: 0.17 | W13: Credit Card | X13: 952.5744
A14: SALE12 | B14: =VLOOKUP(Table6[[#This Row],[Customer_ID]],Table1[[Customer_ID]:[Name]],2,FALSE) -> Wesley Short | C14: =VLOOKUP(Table6[[#This Row],[Customer_ID]],Table1[[Customer_ID]:[City]],5,FALSE) -> Susanstad | D14: =VLOOKUP(Table6[[#This Row],[Customer_ID]],Table1[],3,FALSE) -> 41 | E14: =VLOOKUP(Table6[[#This Row],[Customer_ID]],Table1[],4,FALSE) -> Female | F14: =VLOOKUP(Table6[[#This Row],[Customer_ID]],Table1[],6,FALSE) -> Montana | G14: =VLOOKUP(Table6[[#This Row],[Customer_ID]],Table1[],8,FALSE) -> Gold | H14: CUST1237 | I14: 45528 | J14: PROD88 | K14: =VLOOKUP($J14,'Product_Dim (2)'!$A$2:$G$101,{3,4,5,6},FALSE) -> Sports | L14: =VLOOKUP($J14,'Product_Dim (2)'!$A$2:$G$101,{4,5,6},FALSE) -> Accessories | M14: {=VLOOKUP($J14,'Product_Dim (2)'!$A$2:$G$101,{6},FALSE)} -> 131.24 | N14: =VLOOKUP($J14,'Product_Dim (2)'!$A$2:$G$101,7,FALSE) -> 232 | O14: STORE4 | P14: =VLOOKUP($O14,'Store_Dim (2)'!$A$2:$E$21,2,FALSE) -> Alexander Group | Q14: =VLOOKUP(Table6[[#This Row],[Store_ID]],Table4[],3,FALSE) -> South | R14: =VLOOKUP(Table6[[#This Row],[Store_ID]],Table4[],4,FALSE) -> Port Sharon | S14: =VLOOKUP(Table6[[#This Row],[Store_ID]],Table4[],5,FALSE) -> Online | T14: 4 | U14: 644.58 | V14: 0.01 | W14: Credit Card | X14: 2552.5368
A15: SALE13 | B15: =VLOOKUP(Table6[[#This Row],[Customer_ID]],Table1[[Customer_ID]:[Name]],2,FALSE) -> Adam Castro | C15: =VLOOKUP(Table6[[#This Row],[Customer_ID]],Table1[[Customer_ID]:[City]],5,FALSE) -> New Donnabury | D15: =VLOOKUP(Table6[[#This Row],[Customer_ID]],Table1[],3,FALSE) -> 51 | E15: =VLOOKUP(Table6[[#This Row],[Customer_ID]],Table1[],4,FALSE) -> Male | F15: =VLOOKUP(Table6[[#This Row],[Customer_ID]],Table1[],6,FALSE) -> Texas | G15: =VLOOKUP(Table6[[#This Row],[Customer_ID]],Table1[],8,FALSE) -> Silver | H15: CUST1443 | I15: 45875 | J15: PROD34 | K15: =VLOOKUP($J15,'Product_Dim (2)'!$A$2:$G$101,{3,4,5,6},FALSE) -> Electronics | L15: =VLOOKUP($J15,'Product_Dim (2)'!$A$2:$G$101,{4,5,6},FALSE) -> Computer | M15: {=VLOOKUP($J15,'Product_Dim (2)'!$A$2:$G$101,{6},FALSE)} -> 419.28 | N15: =VLOOKUP($J15,'Product_Dim (2)'!$A$2:$G$101,7,FALSE) -> 86 | O15: STORE16 | P15: =VLOOKUP($O15,'Store_Dim (2)'!$A$2:$E$21,2,FALSE) -> Frederick-Wright | Q15: =VLOOKUP(Table6[[#This Row],[Store_ID]],Table4[],3,FALSE) -> West | R15: =VLOOKUP(Table6[[#This Row],[Store_ID]],Table4[],4,FALSE) -> New Jimmymouth | S15: =VLOOKUP(Table6[[#This Row],[Store_ID]],Table4[],5,FALSE) -> Flagship | T15: 2 | U15: 316.9 | V15: 0.3 | W15: PayPal | X15: 443.66
A16: SALE14 | B16: =VLOOKUP(Table6[[#This Row],[Customer_ID]],Table1[[Customer_ID]:[Name]],2,FALSE) -> Sherry Cabrera | C16: =VLOOKUP(Table6[[#This Row],[Customer_ID]],Table1[[Customer_ID]:[City]],5,FALSE) -> Shannonview | D16: =VLOOKUP(Table6[[#This Row],[Customer_ID]],Table1[],3,FALSE) -> 55 | E16: =VLOOKUP(Table6[[#This Row],[Customer_ID]],Table1[],4,FALSE) -> Male | F16: =VLOOKUP(Table6[[#This Row],[Customer_ID]],Table1[],6,FALSE) -> Pennsylvania | G16: =VLOOKUP(Table6[[#This Row],[Customer_ID]],Table1[],8,FALSE) -> Silver | H16: CUST1348 | I16: 45829 | J16: PROD24 | K16: =VLOOKUP($J16,'Product_Dim (2)'!$A$2:$G$101,{3,4,5,6},FALSE) -> Sports | L16: =VLOOKUP($J16,'Product_Dim (2)'!$A$2:$G$101,{4,5,6},FALSE) -> Outdoor | M16: {=VLOOKUP($J16,'Product_Dim (2)'!$A$2:$G$101,{6},FALSE)} -> 166.06 | N16: =VLOOKUP($J16,'Product_Dim (2)'!$A$2:$G$101,7,FALSE) -> 340 | O16: STORE15 | P16: =VLOOKUP($O16,'Store_Dim (2)'!$A$2:$E$21,2,FALSE) -> Shelton PLC | Q16: =VLOOKUP(Table6[[#This Row],[Store_ID]],Table4[],3,FALSE) -> North | R16: =VLOOKUP(Table6[[#This Row],[Store_ID]],Table4[],4,FALSE) -> East Jenniferstad | S16: =VLOOKUP(Table6[[#This Row],[Store_ID]],Table4[],5,FALSE) -> Flagship | T16: 4 | U16: 403.47 | V16: 0.29 | W16: PayPal | X16: 1145.8548
A17: SALE15 | B17: =VLOOKUP(Table6[[#This Row],[Customer_ID]],Table1[[Customer_ID]:[Name]],2,FALSE) -> Lindsay Beasley | C17: =VLOOKUP(Table6[[#This Row],[Customer_ID]],Table1[[Customer_ID]:[City]],5,FALSE) -> Wesleyhaven | D17: =VLOOKUP(Table6[[#This Row],[Customer_ID]],Table1[],3,FALSE) -> 37 | E17: =VLOOKUP(Table6[[#This Row],[Customer_ID]],Table1[],4,FALSE) -> Female | F17: =VLOOKUP(Table6[[#This Row],[Customer_ID]],Table1[],6,FALSE) -> Idaho | G17: =VLOOKUP(Table6[[#This Row],[Customer_ID]],Table1[],8,FALSE) -> Silver | H17: CUST1435 | I17: 45636 | J17: PROD36 | K17: =VLOOKUP($J17,'Product_Dim (2)'!$A$2:$G$101,{3,4,5,6},FALSE) -> Clothing | L17: =VLOOKUP($J17,'Product_Dim (2)'!$A$2:$G$101,{4,5,6},FALSE) -> Tops | M17: {=VLOOKUP($J17,'Product_Dim (2)'!$A$2:$G$101,{6},FALSE)} -> 223.43 | N17: =VLOOKUP($J17,'Product_Dim (2)'!$A$2:$G$101,7,FALSE) -> 154 | O17: STORE9 | P17: =VLOOKUP($O17,'Store_Dim (2)'!$A$2:$E$21,2,FALSE) -> Moore, Padilla and Butler | Q17: =VLOOKUP(Table6[[#This Row],[Store_ID]],Table4[],3,FALSE) -> South | R17: =VLOOKUP(Table6[[#This Row],[Store_ID]],Table4[],4,FALSE) -> East Johnstad | S17: =VLOOKUP(Table6[[#This Row],[Store_ID]],Table4[],5,FALSE) -> Flagship | T17: =X17/(U17*(1-V17)) -> 3 | U17: 871.34 | V17: 0.04 | W17: COD | X17: 2509.4592
A18: SALE16 | B18: =VLOOKUP(Table6[[#This Row],[Customer_ID]],Table1[[Customer_ID]:[Name]],2,FALSE) -> Arthur Warren | C18: =VLOOKUP(Table6[[#This Row],[Customer_ID]],Table1[[Customer_ID]:[City]],5,FALSE) -> Ericshire | D18: =VLOOKUP(Table6[[#This Row],[Customer_ID]],Table1[],3,FALSE) -> 38 | E18: =VLOOKUP(Table6[[#This Row],[Customer_ID]],Table1[],4,FALSE) -> Male | F18: =VLOOKUP(Table6[[#This Row],[Customer_ID]],Table1[],6,FALSE) -> Nevada | G18: =VLOOKUP(Table6[[#This Row],[Customer_ID]],Table1[],8,FALSE) -> Gold | H18: CUST1276 | I18: 45913 | J18: PROD65 | K18: =VLOOKUP($J18,'Product_Dim (2)'!$A$2:$G$101,{3,4,5,6},FALSE) -> Sports | L18: =VLOOKUP($J18,'Product_Dim (2)'!$A$2:$G$101,{4,5,6},FALSE) -> Fitness | M18: {=VLOOKUP($J18,'Product_Dim (2)'!$A$2:$G$101,{6},FALSE)} -> 240.63 | N18: =VLOOKUP($J18,'Product_Dim (2)'!$A$2:$G$101,7,FALSE) -> 423 | O18: STORE19 | P18: =VLOOKUP($O18,'Store_Dim (2)'!$A$2:$E$21,2,FALSE) -> Mann-Austin | Q18: =VLOOKUP(Table6[[#This Row],[Store_ID]],Table4[],3,FALSE) -> East | R18: =VLOOKUP(Table6[[#This Row],[Store_ID]],Table4[],4,FALSE) -> Vasquezborough | S18: =VLOOKUP(Table6[[#This Row],[Store_ID]],Table4[],5,FALSE) -> Online | T18: 2 | U18: 451.98 | V18: 0.25 | W18: Credit Card | X18: 677.97
A19: SALE17 | B19: =VLOOKUP(Table6[[#This Row],[Customer_ID]],Table1[[Customer_ID]:[Name]],2,FALSE) -> Molly Gardner | C19: =VLOOKUP(Table6[[#This Row],[Customer_ID]],Table1[[Customer_ID]:[City]],5,FALSE) -> Nicoleborough | D19: =VLOOKUP(Table6[[#This Row],[Customer_ID]],Table1[],3,FALSE) -> 22 | E19: =VLOOKUP(Table6[[#This Row],[Customer_ID]],Table1[],4,FALSE) -> Female | F19: =VLOOKUP(Table6[[#This Row],[Customer_ID]],Table1[],6,FALSE) -> Arkansas | G19: =VLOOKUP(Table6[[#This Row],[Customer_ID]],Table1[],8,FALSE) -> Platinum | H19: CUST1079 | I19: 45637 | J19: PROD27 | K19: =VLOOKUP($J19,'Product_Dim (2)'!$A$2:$G$101,{3,4,5,6},FALSE) -> Home | L19: =VLOOKUP($J19,'Product_Dim (2)'!$A$2:$G$101,{4,5,6},FALSE) -> Decor | M19: {=VLOOKUP($J19,'Product_Dim (2)'!$A$2:$G$101,{6},FALSE)} -> 234.806 | N19: =VLOOKUP($J19,'Product_Dim (2)'!$A$2:$G$101,7,FALSE) -> 378 | O19: STORE4 | P19: =VLOOKUP($O19,'Store_Dim (2)'!$A$2:$E$21,2,FALSE) -> Alexander Group | Q19: =VLOOKUP(Table6[[#This Row],[Store_ID]],Table4[],3,FALSE) -> South | R19: =VLOOKUP(Table6[[#This Row],[Store_ID]],Table4[],4,FALSE) -> Port Sharon | S19: =VLOOKUP(Table6[[#This Row],[Store_ID]],Table4[],5,FALSE) -> Online | T19: 2 | U19: 502.69 | V19: 0.23 | W19: Credit Card | X19: 774.1426
A20: SALE18 | B20: =VLOOKUP(Table6[[#This Row],[Customer_ID]],Table1[[Customer_ID]:[Name]],2,FALSE) -> David Patterson | C20: =VLOOKUP(Table6[[#This Row],[Customer_ID]],Table1[[Customer_ID]:[City]],5,FALSE) -> New Amyport | D20: =VLOOKUP(Table6[[#This Row],[Customer_ID]],Table1[],3,FALSE) -> 43 | E20: =VLOOKUP(Table6[[#This Row],[Customer_ID]],Table1[],4,FALSE) -> Female | F20: =VLOOKUP(Table6[[#This Row],[Customer_ID]],Table1[],6,FALSE) -> Nevada | G20: =VLOOKUP(Table6[[#This Row],[Customer_ID]],Table1[],8,FALSE) -> Gold | H20: CUST1094 | I20: 45517 | J20: PROD39 | K20: =VLOOKUP($J20,'Product_Dim (2)'!$A$2:$G$101,{3,4,5,6},FALSE) -> Electronics | L20: =VLOOKUP($J20,'Product_Dim (2)'!$A$2:$G$101,{4,5,6},FALSE) -> Mobile | M20: {=VLOOKUP($J20,'Product_Dim (2)'!$A$2:$G$101,{6},FALSE)} -> 326.06 | N20: =VLOOKUP($J20,'Product_Dim (2)'!$A$2:$G$101,7,FALSE) -> 301 | O20: STORE4 | P20: =VLOOKUP($O20,'Store_Dim (2)'!$A$2:$E$21,2,FALSE) -> Alexander Group | Q20: =VLOOKUP(Table6[[#This Row],[Store_ID]],Table4[],3,FALSE) -> South | R20: =VLOOKUP(Table6[[#This Row],[Store_ID]],Table4[],4,FALSE) -> Port Sharon | S20: =VLOOKUP(Table6[[#This Row],[Store_ID]],Table4[],5,FALSE) -> Online | T20: 2 | U20: 559.23 | V20: 0.25 | W20: COD | X20: 838.845
A21: SALE19 | B21: =VLOOKUP(Table6[[#This Row],[Customer_ID]],Table1[[Customer_ID]:[Name]],2,FALSE) -> Maria Hill | C21: =VLOOKUP(Table6[[#This Row],[Customer_ID]],Table1[[Customer_ID]:[City]],5,FALSE) -> Zamoraborough | D21: =VLOOKUP(Table6[[#This Row],[Customer_ID]],Table1[],3,FALSE) -> 58 | E21: =VLOOKUP(Table6[[#This Row],[Customer_ID]],Table1[],4,FALSE) -> Female | F21: =VLOOKUP(Table6[[#This Row],[Customer_ID]],Table1[],6,FALSE) -> Nevada | G21: =VLOOKUP(Table6[[#This Row],[Customer_ID]],Table1[],8,FALSE) -> Platinum | H21: CUST1239 | I21: 45369 | J21: PROD60 | K21: =VLOOKUP($J21,'Product_Dim (2)'!$A$2:$G$101,{3,4,5,6},FALSE) -> Beauty | L21: =VLOOKUP($J21,'Product_Dim (2)'!$A$2:$G$101,{4,5,6},FALSE) -> Fragrance | M21: {=VLOOKUP($J21,'Product_Dim (2)'!$A$2:$G$101,{6},FALSE)} -> 482.75 | N21: =VLOOKUP($J21,'Product_Dim (2)'!$A$2:$G$101,7,FALSE) -> 444 | O21: STORE13 | P21: =VLOOKUP($O21,'Store_Dim (2)'!$A$2:$E$21,2,FALSE) -> Gardner, Humphrey and Contreras | Q21: =VLOOKUP(Table6[[#This Row],[Store_ID]],Table4[],3,FALSE) -> East | R21: =VLOOKUP(Table6[[#This Row],[Store_ID]],Table4[],4,FALSE) -> Johnsonville | S21: =VLOOKUP(Table6[[#This Row],[Store_ID]],Table4[],5,FALSE) -> Flagship | T21: 4 | U21: =X21/(T21*(1-V21)) -> 464.18 | V21: 0.04 | W21: COD | X21: 1782.4512
A22: SALE20 | B22: =VLOOKUP(Table6[[#This Row],[Customer_ID]],Table1[[Customer_ID]:[Name]],2,FALSE) -> Justin Cross | C22: =VLOOKUP(Table6[[#This Row],[Customer_ID]],Table1[[Customer_ID]:[City]],5,FALSE) -> North Anthonychester | D22: =VLOOKUP(Table6[[#This Row],[Customer_ID]],Table1[],3,FALSE) -> 62 | E22: =VLOOKUP(Table6[[#This Row],[Customer_ID]],Table1[],4,FALSE) -> Female | F22: =VLOOKUP(Table6[[#This Row],[Customer_ID]],Table1[],6,FALSE) -> Nevada | G22: =VLOOKUP(Table6[[#This Row],[Customer_ID]],Table1[],8,FALSE) -> Bronze | H22: CUST1144 | I22: 45843 | J22: PROD72 | K22: =VLOOKUP($J22,'Product_Dim (2)'!$A$2:$G$101,{3,4,5,6},FALSE) -> Sports | L22: =VLOOKUP($J22,'Product_Dim (2)'!$A$2:$G$101,{4,5,6},FALSE) -> Fitness | M22: {=VLOOKUP($J22,'Product_Dim (2)'!$A$2:$G$101,{6},FALSE)} -> 477.61 | N22: =VLOOKUP($J22,'Product_Dim (2)'!$A$2:$G$101,7,FALSE) -> 300 | O22: STORE17 | P22: =VLOOKUP($O22,'Store_Dim (2)'!$A$2:$E$21,2,FALSE) -> Holloway Ltd | Q22: =VLOOKUP(Table6[[#This Row],[Store_ID]],Table4[],3,FALSE) -> North | R22: =VLOOKUP(Table6[[#This Row],[Store_ID]],Table4[],4,FALSE) -> Bensonhaven | S22: =VLOOKUP(Table6[[#This Row],[Store_ID]],Table4[],5,FALSE) -> Flagship | T22: 3 | U22: 986.04 | V22: 0.27 | W22: COD | X22: 2159.4276
A23: SALE21 | B23: =VLOOKUP(Table6[[#This Row],[Customer_ID]],Table1[[Customer_ID]:[Name]],2,FALSE) -> Alexander Byrd | C23: =VLOOKUP(Table6[[#This Row],[Customer_ID]],Table1[[Customer_ID]:[City]],5,FALSE) -> Parkerview | D23: =VLOOKUP(Table6[[#This Row],[Customer_ID]],Table1[],3,FALSE) -> 25 | E23: =VLOOKUP(Table6[[#This Row],[Customer_ID]],Table1[],4,FALSE) -> Female | F23: =VLOOKUP(Table6[[#This Row],[Customer_ID]],Table1[],6,FALSE) -> New York | G23: =VLOOKUP(Table6[[#This Row],[Customer_ID]],Table1[],8,FALSE) -> Silver | H23: CUST1396 | I23: 45447 | J23: PROD43 | K23: =VLOOKUP($J23,'Product_Dim (2)'!$A$2:$G$101,{3,4,5,6},FALSE) -> Electronics | L23: =VLOOKUP($J23,'Product_Dim (2)'!$A$2:$G$101,{4,5,6},FALSE) -> Computer | M23: {=VLOOKUP($J23,'Product_Dim (2)'!$A$2:$G$101,{6},FALSE)} -> 253.33 | N23: =VLOOKUP($J23,'Product_Dim (2)'!$A$2:$G$101,7,FALSE) -> 266 | O23: STORE18 | P23: =VLOOKUP($O23,'Store_Dim (2)'!$A$2:$E$21,2,FALSE) -> Guerrero-Schmitt | Q23: =VLOOKUP(Table6[[#This Row],[Store_ID]],Table4[],3,FALSE) -> East | R23: =VLOOKUP(Table6[[#This Row],[Store_ID]],Table4[],4,FALSE) -> East Stevechester | S23: =VLOOKUP(Table6[[#This Row],[Store_ID]],Table4[],5,FALSE) -> Flagship | T23: 1 | U23: 589.56 | V23: 0.22 | W23: Credit Card | X23: 459.8568
A24: SALE22 | B24: =VLOOKUP(Table6[[#This Row],[Customer_ID]],Table1[[Customer_ID]:[Name]],2,FALSE) -> Elizabeth Foster | C24: =VLOOKUP(Table6[[#This Row],[Customer_ID]],Table1[[Customer_ID]:[City]],5,FALSE) -> Anthonymouth | D24: =VLOOKUP(Table6[[#This Row],[Customer_ID]],Table1[],3,FALSE) -> 33 | E24: =VLOOKUP(Table6[[#This Row],[Customer_ID]],Table1[],4,FALSE) -> Female | F24: =VLOOKUP(Table6[[#This Row],[Customer_ID]],Table1[],6,FALSE) -> Oklahoma | G24: =VLOOKUP(Table6[[#This Row],[Customer_ID]],Table1[],8,FALSE) -> Gold | H24: CUST1476 | I24: 45394 | J24: PROD69 | K24: =VLOOKUP($J24,'Product_Dim (2)'!$A$2:$G$101,{3,4,5,6},FALSE) -> Clothing | L24: =VLOOKUP($J24,'Product_Dim (2)'!$A$2:$G$101,{4,5,6},FALSE) -> Bottoms | M24: {=VLOOKUP($J24,'Product_Dim (2)'!$A$2:$G$101,{6},FALSE)} -> 218.22 | N24: =VLOOKUP($J24,'Product_Dim (2)'!$A$2:$G$101,7,FALSE) -> 224 | O24: STORE10 | P24: =VLOOKUP($O24,'Store_Dim (2)'!$A$2:$E$21,2,FALSE) -> Hill, Wagner and Ballard | Q24: =VLOOKUP(Table6[[#This Row],[Store_ID]],Table4[],3,FALSE) -> East | R24: =VLOOKUP(Table6[[#This Row],[Store_ID]],Table4[],4,FALSE) -> East Davidville | S24: =VLOOKUP(Table6[[#This Row],[Store_ID]],Table4[],5,FALSE) -> Online | T24: 3 | U24: 979.42 | V24: 0.03 | W24: PayPal | X24: 2850.1122
A25: SALE23 | B25: =VLOOKUP(Table6[[#This Row],[Customer_ID]],Table1[[Customer_ID]:[Name]],2,FALSE) -> Miranda King | C25: =VLOOKUP(Table6[[#This Row],[Customer_ID]],Table1[[Customer_ID]:[City]],5,FALSE) -> West Mathew | D25: =VLOOKUP(Table6[[#This Row],[Customer_ID]],Table1[],3,FALSE) -> 34 | E25: =VLOOKUP(Table6[[#This Row],[Customer_ID]],Table1[],4,FALSE) -> Female | F25: =VLOOKUP(Table6[[#This Row],[Customer_ID]],Table1[],6,FALSE) -> New York | G25: =VLOOKUP(Table6[[#This Row],[Customer_ID]],Table1[],8,FALSE) -> Platinum | H25: CUST1368 | I25: 45466 | J25: PROD12 | K25: =VLOOKUP($J25,'Product_Dim (2)'!$A$2:$G$101,{3,4,5,6},FALSE) -> Beauty | L25: =VLOOKUP($J25,'Product_Dim (2)'!$A$2:$G$101,{4,5,6},FALSE) -> Haircare | M25: {=VLOOKUP($J25,'Product_Dim (2)'!$A$2:$G$101,{6},FALSE)} -> 115.82 | N25: =VLOOKUP($J25,'Product_Dim (2)'!$A$2:$G$101,7,FALSE) -> 460 | O25: STORE8 | P25: =VLOOKUP($O25,'Store_Dim (2)'!$A$2:$E$21,2,FALSE) -> Bean, Jones and Park | Q25: =VLOOKUP(Table6[[#This Row],[Store_ID]],Table4[],3,FALSE) -> West | R25: =VLOOKUP(Table6[[#This Row],[Store_ID]],Table4[],4,FALSE) -> Thompsonborough | S25: =VLOOKUP(Table6[[#This Row],[Store_ID]],Table4[],5,FALSE) -> Online | T25: 1 | U25: 719.28 | V25: 0.08 | W25: Credit Card | X25: 661.7376
A26: SALE24 | B26: =VLOOKUP(Table6[[#This Row],[Customer_ID]],Table1[[Customer_ID]:[Name]],2,FALSE) -> Jennifer Pruitt | C26: =VLOOKUP(Table6[[#This Row],[Customer_ID]],Table1[[Customer_ID]:[City]],5,FALSE) -> East Justin | D26: =VLOOKUP(Table6[[#This Row],[Customer_ID]],Table1[],3,FALSE) -> 53 | E26: =VLOOKUP(Table6[[#This Row],[Customer_ID]],Table1[],4,FALSE) -> Male | F26: =VLOOKUP(Table6[[#This Row],[Customer_ID]],Table1[],6,FALSE) -> Missouri | G26: =VLOOKUP(Table6[[#This Row],[Customer_ID]],Table1[],8,FALSE) -> Silver | H26: CUST1186 | I26: 45908 | J26: PROD67 | K26: =VLOOKUP($J26,'Product_Dim (2)'!$A$2:$G$101,{3,4,5,6},FALSE) -> Electronics | L26: =VLOOKUP($J26,'Product_Dim (2)'!$A$2:$G$101,{4,5,6},FALSE) -> Accessories | M26: {=VLOOKUP($J26,'Product_Dim (2)'!$A$2:$G$101,{6},FALSE)} -> 349.17 | N26: =VLOOKUP($J26,'Product_Dim (2)'!$A$2:$G$101,7,FALSE) -> 476 | O26: STORE6 | P26: =VLOOKUP($O26,'Store_Dim (2)'!$A$2:$E$21,2,FALSE) -> Benson-Elliott | Q26: =VLOOKUP(Table6[[#This Row],[Store_ID]],Table4[],3,FALSE) -> East | R26: =VLOOKUP(Table6[[#This Row],[Store_ID]],Table4[],4,FALSE) -> Port Josephberg | S26: =VLOOKUP(Table6[[#This Row],[Store_ID]],Table4[],5,FALSE) -> Online | T26: 3 | U26: 77.6 | V26: 0.07 | W26: Credit Card | X26: 216.504
A27: SALE25 | B27: =VLOOKUP(Table6[[#This Row],[Customer_ID]],Table1[[Customer_ID]:[Name]],2,FALSE) -> Erika Padilla | C27: =VLOOKUP(Table6[[#This Row],[Customer_ID]],Table1[[Customer_ID]:[City]],5,FALSE) -> Andrewsland | D27: =VLOOKUP(Table6[[#This Row],[Customer_ID]],Table1[],3,FALSE) -> 50 | E27: =VLOOKUP(Table6[[#This Row],[Customer_ID]],Table1[],4,FALSE) -> Male | F27: =VLOOKUP(Table6[[#This Row],[Customer_ID]],Table1[],6,FALSE) -> Alabama | G27: =VLOOKUP(Table6[[#This Row],[Customer_ID]],Table1[],8,FALSE) -> Silver | H27: CUST1381 | I27: 45552 | J27: PROD5 | K27: =VLOOKUP($J27,'Product_Dim (2)'!$A$2:$G$101,{3,4,5,6},FALSE) -> Clothing | L27: =VLOOKUP($J27,'Product_Dim (2)'!$A$2:$G$101,{4,5,6},FALSE) -> Accessories | M27: {=VLOOKUP($J27,'Product_Dim (2)'!$A$2:$G$101,{6},FALSE)} -> 261 | N27: =VLOOKUP($J27,'Product_Dim (2)'!$A$2:$G$101,7,FALSE) -> 59 | O27: STORE3 | P27: =VLOOKUP($O27,'Store_Dim (2)'!$A$2:$E$21,2,FALSE) -> Johnson-Wright | Q27: =VLOOKUP(Table6[[#This Row],[Store_ID]],Table4[],3,FALSE) -> North | R27: =VLOOKUP(Table6[[#This Row],[Store_ID]],Table4[],4,FALSE) -> Hoodberg | S27: =VLOOKUP(Table6[[#This Row],[Store_ID]],Table4[],5,FALSE) -> Outlet | T27: 4 | U27: 852.71 | V27: 0.14 | W27: PayPal | X27: 2933.3224
A28: SALE26 | B28: =VLOOKUP(Table6[[#This Row],[Customer_ID]],Table1[[Customer_ID]:[Name]],2,FALSE) -> Stuart Johnson | C28: =VLOOKUP(Table6[[#This Row],[Customer_ID]],Table1[[Customer_ID]:[City]],5,FALSE) -> West Markport | D28: =VLOOKUP(Table6[[#This Row],[Customer_ID]],Table1[],3,FALSE) -> 42 | E28: =VLOOKUP(Table6[[#This Row],[Customer_ID]],Table1[],4,FALSE) -> Female | F28: =VLOOKUP(Table6[[#This Row],[Customer_ID]],Table1[],6,FALSE) -> North Dakota | G28: =VLOOKUP(Table6[[#This Row],[Customer_ID]],Table1[],8,FALSE) -> Platinum | H28: CUST1213 | I28: 45294 | J28: PROD98 | K28: =VLOOKUP($J28,'Product_Dim (2)'!$A$2:$G$101,{3,4,5,6},FALSE) -> Electronics | L28: =VLOOKUP($J28,'Product_Dim (2)'!$A$2:$G$101,{4,5,6},FALSE) -> Audio | M28: {=VLOOKUP($J28,'Product_Dim (2)'!$A$2:$G$101,{6},FALSE)} -> 431.67 | N28: =VLOOKUP($J28,'Product_Dim (2)'!$A$2:$G$101,7,FALSE) -> 73 | O28: STORE8 | P28: =VLOOKUP($O28,'Store_Dim (2)'!$A$2:$E$21,2,FALSE) -> Bean, Jones and Park | Q28: =VLOOKUP(Table6[[#This Row],[Store_ID]],Table4[],3,FALSE) -> West | R28: =VLOOKUP(Table6[[#This Row],[Store_ID]],Table4[],4,FALSE) -> Thompsonborough | S28: =VLOOKUP(Table6[[#This Row],[Store_ID]],Table4[],5,FALSE) -> Online | T28: 4 | U28: 156.16 | V28: =1-(X28/(T28*U28)) -> 0.04 | W28: Credit Card | X28: 599.6544
A29: SALE27 | B29: =VLOOKUP(Table6[[#This Row],[Customer_ID]],Table1[[Customer_ID]:[Name]],2,FALSE) -> Anna Perez | C29: =VLOOKUP(Table6[[#This Row],[Customer_ID]],Table1[[Customer_ID]:[City]],5,FALSE) -> South Jerry | D29: =VLOOKUP(Table6[[#This Row],[Customer_ID]],Table1[],3,FALSE) -> 30 | E29: =VLOOKUP(Table6[[#This Row],[Customer_ID]],Table1[],4,FALSE) -> Male | F29: =VLOOKUP(Table6[[#This Row],[Customer_ID]],Table1[],6,FALSE) -> Maine | G29: =VLOOKUP(Table6[[#This Row],[Customer_ID]],Table1[],8,FALSE) -> Platinum | H29: CUST1200 | I29: 45710 | J29: PROD77 | K29: =VLOOKUP($J29,'Product_Dim (2)'!$A$2:$G$101,{3,4,5,6},FALSE) -> Electronics | L29: =VLOOKUP($J29,'Product_Dim (2)'!$A$2:$G$101,{4,5,6},FALSE) -> Appliances | M29: {=VLOOKUP($J29,'Product_Dim (2)'!$A$2:$G$101,{6},FALSE)} -> 480.9 | N29: =VLOOKUP($J29,'Product_Dim (2)'!$A$2:$G$101,7,FALSE) -> 104 | O29: STORE8 | P29: =VLOOKUP($O29,'Store_Dim (2)'!$A$2:$E$21,2,FALSE) -> Bean, Jones and Park | Q29: =VLOOKUP(Table6[[#This Row],[Store_ID]],Table4[],3,FALSE) -> West | R29: =VLOOKUP(Table6[[#This Row],[Store_ID]],Table4[],4,FALSE) -> Thompsonborough | S29: =VLOOKUP(Table6[[#This Row],[Store_ID]],Table4[],5,FALSE) -> Online | T29: 3 | U29: 815.49 | V29: 0.17 | W29: Credit Card | X29: 2030.5701
A30: SALE28 | B30: =VLOOKUP(Table6[[#This Row],[Customer_ID]],Table1[[Customer_ID]:[Name]],2,FALSE) -> Theresa Campbell | C30: =VLOOKUP(Table6[[#This Row],[Customer_ID]],Table1[[Customer_ID]:[City]],5,FALSE) -> New Brian | D30: =VLOOKUP(Table6[[#This Row],[Customer_ID]],Table1[],3,FALSE) -> 42 | E30: =VLOOKUP(Table6[[#This Row],[Customer_ID]],Table1[],4,FALSE) -> Female | F30: =VLOOKUP(Table6[[#This Row],[Customer_ID]],Table1[],6,FALSE) -> Wisconsin | G30: =VLOOKUP(Table6[[#This Row],[Customer_ID]],Table1[],8,FALSE) -> Bronze | H30: CUST1148 | I30: 45923 | J30: PROD13 | K30: =VLOOKUP($J30,'Product_Dim (2)'!$A$2:$G$101,{3,4,5,6},FALSE) -> Electronics | L30: =VLOOKUP($J30,'Product_Dim (2)'!$A$2:$G$101,{4,5,6},FALSE) -> Accessories | M30: {=VLOOKUP($J30,'Product_Dim (2)'!$A$2:$G$101,{6},FALSE)} -> 242.23 | N30: =VLOOKUP($J30,'Product_Dim (2)'!$A$2:$G$101,7,FALSE) -> 453 | O30: STORE2 | P30: =VLOOKUP($O30,'Store_Dim (2)'!$A$2:$E$21,2,FALSE) -> Black-Horn | Q30: =VLOOKUP(Table6[[#This Row],[Store_ID]],Table4[],3,FALSE) -> South | R30: =VLOOKUP(Table6[[#This Row],[Store_ID]],Table4[],4,FALSE) -> North Nancyview | S30: =VLOOKUP(Table6[[#This Row],[Store_ID]],Table4[],5,FALSE) -> Outlet | T30: 2 | U30: 74.21 | V30: 0.11 | W30: PayPal | X30: 132.0938
A31: SALE29 | B31: =VLOOKUP(Table6[[#This Row],[Customer_ID]],Table1[[Customer_ID]:[Name]],2,FALSE) -> Sherry Cabrera | C31: =VLOOKUP(Table6[[#This Row],[Customer_ID]],Table1[[Customer_ID]:[City]],5,FALSE) -> Shannonview | D31: =VLOOKUP(Table6[[#This Row],[Customer_ID]],Table1[],3,FALSE) -> 55 | E31: =VLOOKUP(Table6[[#This Row],[Customer_ID]],Table1[],4,FALSE) -> Male | F31: =VLOOKUP(Table6[[#This Row],[Customer_ID]],Table1[],6,FALSE) -> Pennsylvania | G31: =VLOOKUP(Table6[[#This Row],[Customer_ID]],Table1[],8,FALSE) -> Silver | H31: CUST1348 | I31: 45302 | J31: PROD99 | K31: =VLOOKUP($J31,'Product_Dim (2)'!$A$2:$G$101,{3,4,5,6},FALSE) -> Home | L31: =VLOOKUP($J31,'Product_Dim (2)'!$A$2:$G$101,{4,5,6},FALSE) -> Kitchen | M31: {=VLOOKUP($J31,'Product_Dim (2)'!$A$2:$G$101,{6},FALSE)} -> 201.41 | N31: =VLOOKUP($J31,'Product_Dim (2)'!$A$2:$G$101,7,FALSE) -> 146 | O31: STORE3 | P31: =VLOOKUP($O31,'Store_Dim (2)'!$A$2:$E$21,2,FALSE) -> Johnson-Wright | Q31: =VLOOKUP(Table6[[#This Row],[Store_ID]],Table4[],3,FALSE) -> North | R31: =VLOOKUP(Table6[[#This Row],[Store_ID]],Table4[],4,FALSE) -> Hoodberg | S31: =VLOOKUP(Table6[[#This Row],[Store_ID]],Table4[],5,FALSE) -> Outlet | T31: =X31/(U31*(1-V31)) -> 4 | U31: 451.67 | V31: 0.15 | W31: Credit Card | X31: 1535.678
A32: SALE30 | B32: =VLOOKUP(Table6[[#This Row],[Customer_ID]],Table1[[Customer_ID]:[Name]],2,FALSE) -> Joshua Ryan | C32: =VLOOKUP(Table6[[#This Row],[Customer_ID]],Table1[[Customer_ID]:[City]],5,FALSE) -> New David | D32: =VLOOKUP(Table6[[#This Row],[Customer_ID]],Table1[],3,FALSE) -> 27 | E32: =VLOOKUP(Table6[[#This Row],[Customer_ID]],Table1[],4,FALSE) -> Female | F32: =VLOOKUP(Table6[[#This Row],[Customer_ID]],Table1[],6,FALSE) -> New Jersey | G32: =VLOOKUP(Table6[[#This Row],[Customer_ID]],Table1[],8,FALSE) -> Platinum | H32: CUST1028 | I32: 45217 | J32: PROD5 | K32: =VLOOKUP($J32,'Product_Dim (2)'!$A$2:$G$101,{3,4,5,6},FALSE) -> Clothing | L32: =VLOOKUP($J32,'Product_Dim (2)'!$A$2:$G$101,{4,5,6},FALSE) -> Accessories | M32: {=VLOOKUP($J32,'Product_Dim (2)'!$A$2:$G$101,{6},FALSE)} -> 261 | N32: =VLOOKUP($J32,'Product_Dim (2)'!$A$2:$G$101,7,FALSE) -> 59 | O32: STORE19 | P32: =VLOOKUP($O32,'Store_Dim (2)'!$A$2:$E$21,2,FALSE) -> Mann-Austin | Q32: =VLOOKUP(Table6[[#This Row],[Store_ID]],Table4[],3,FALSE) -> East | R32: =VLOOKUP(Table6[[#This Row],[Store_ID]],Table4[],4,FALSE) -> Vasquezborough | S32: =VLOOKUP(Table6[[#This Row],[Store_ID]],Table4[],5,FALSE) -> Online | T32: 1 | U32: 429.38 | V32: 0.13 | W32: PayPal | X32: 373.5606
A33: SALE31 | B33: =VLOOKUP(Table6[[#This Row],[Customer_ID]],Table1[[Customer_ID]:[Name]],2,FALSE) -> Shane Brown | C33: =VLOOKUP(Table6[[#This Row],[Customer_ID]],Table1[[Customer_ID]:[City]],5,FALSE) -> East Andrea | D33: =VLOOKUP(Table6[[#This Row],[Customer_ID]],Table1[],3,FALSE) -> 23 | E33: =VLOOKUP(Table6[[#This Row],[Customer_ID]],Table1[],4,FALSE) -> Female | F33: =VLOOKUP(Table6[[#This Row],[Customer_ID]],Table1[],6,FALSE) -> Michigan | G33: =VLOOKUP(Table6[[#This Row],[Customer_ID]],Table1[],8,FALSE) -> Gold | H33: CUST1412 | I33: 45593 | J33: PROD53 | K33: =VLOOKUP($J33,'Product_Dim (2)'!$A$2:$G$101,{3,4,5,6},FALSE) -> Clothing | L33: =VLOOKUP($J33,'Product_Dim (2)'!$A$2:$G$101,{4,5,6},FALSE) -> Bottoms | M33: {=VLOOKUP($J33,'Product_Dim (2)'!$A$2:$G$101,{6},FALSE)} -> 386.56 | N33: =VLOOKUP($J33,'Product_Dim (2)'!$A$2:$G$101,7,FALSE) -> 125 | O33: STORE12 | P33: =VLOOKUP($O33,'Store_Dim (2)'!$A$2:$E$21,2,FALSE) -> Thomas, Bridges and Harris | Q33: =VLOOKUP(Table6[[#This Row],[Store_ID]],Table4[],3,FALSE) -> North | R33: =VLOOKUP(Table6[[#This Row],[Store_ID]],Table4[],4,FALSE) -> Sabrinatown | S33: =VLOOKUP(Table6[[#This Row],[Store_ID]],Table4[],5,FALSE) -> Online | T33: 2 | U33: 148.96 | V33: 0.03 | W33: COD | X33: 288.9824
A34: SALE32 | B34: =VLOOKUP(Table6[[#This Row],[Customer_ID]],Table1[[Customer_ID]:[Name]],2,FALSE) -> Jennifer Johnson | C34: =VLOOKUP(Table6[[#This Row],[Customer_ID]],Table1[[Customer_ID]:[City]],5,FALSE) -> Cheyenneborough | D34: =VLOOKUP(Table6[[#This Row],[Customer_ID]],Table1[],3,FALSE) -> 54 | E34: =VLOOKUP(Table6[[#This Row],[Customer_ID]],Table1[],4,FALSE) -> Male | F34: =VLOOKUP(Table6[[#This Row],[Customer_ID]],Table1[],6,FALSE) -> New Hampshire | G34: =VLOOKUP(Table6[[#This Row],[Customer_ID]],Table1[],8,FALSE) -> Bronze | H34: CUST1398 | I34: 45597 | J34: PROD75 | K34: =VLOOKUP($J34,'Product_Dim (2)'!$A$2:$G$101,{3,4,5,6},FALSE) -> Clothing | L34: =VLOOKUP($J34,'Product_Dim (2)'!$A$2:$G$101,{4,5,6},FALSE) -> Footwear | M34: {=VLOOKUP($J34,'Product_Dim (2)'!$A$2:$G$101,{6},FALSE)} -> 158.14 | N34: =VLOOKUP($J34,'Product_Dim (2)'!$A$2:$G$101,7,FALSE) -> 82 | O34: STORE8 | P34: =VLOOKUP($O34,'Store_Dim (2)'!$A$2:$E$21,2,FALSE) -> Bean, Jones and Park | Q34: =VLOOKUP(Table6[[#This Row],[Store_ID]],Table4[],3,FALSE) -> West | R34: =VLOOKUP(Table6[[#This Row],[Store_ID]],Table4[],4,FALSE) -> Thompsonborough | S34: =VLOOKUP(Table6[[#This Row],[Store_ID]],Table4[],5,FALSE) -> Online | T34: 4 | U34: 313.83 | V34: 0.08 | W34: Credit Card | X34: 1154.8944
A35: SALE33 | B35: =VLOOKUP(Table6[[#This Row],[Customer_ID]],Table1[[Customer_ID]:[Name]],2,FALSE) -> April Phillips | C35: =VLOOKUP(Table6[[#This Row],[Customer_ID]],Table1[[Customer_ID]:[City]],5,FALSE) -> Lake Carolyn | D35: =VLOOKUP(Table6[[#This Row],[Customer_ID]],Table1[],3,FALSE) -> 62 | E35: =VLOOKUP(Table6[[#This Row],[Customer_ID]],Table1[],4,FALSE) -> Female | F35: =VLOOKUP(Table6[[#This Row],[Customer_ID]],Table1[],6,FALSE) -> Hawaii | G35: =VLOOKUP(Table6[[#This Row],[Customer_ID]],Table1[],8,FALSE) -> Platinum | H35: CUST1453 | I35: 45620 | J35: PROD12 | K35: =VLOOKUP($J35,'Product_Dim (2)'!$A$2:$G$101,{3,4,5,6},FALSE) -> Beauty | L35: =VLOOKUP($J35,'Product_Dim (2)'!$A$2:$G$101,{4,5,6},FALSE) -> Haircare | M35: {=VLOOKUP($J35,'Product_Dim (2)'!$A$2:$G$101,{6},FALSE)} -> 115.82 | N35: =VLOOKUP($J35,'Product_Dim (2)'!$A$2:$G$101,7,FALSE) -> 460 | O35: STORE6 | P35: =VLOOKUP($O35,'Store_Dim (2)'!$A$2:$E$21,2,FALSE) -> Benson-Elliott | Q35: =VLOOKUP(Table6[[#This Row],[Store_ID]],Table4[],3,FALSE) -> East | R35: =VLOOKUP(Table6[[#This Row],[Store_ID]],Table4[],4,FALSE) -> Port Josephberg | S35: =VLOOKUP(Table6[[#This Row],[Store_ID]],Table4[],5,FALSE) -> Online | T35: 2 | U35: 717.31 | V35: 0.15 | W35: Credit Card | X35: 1219.427
A36: SALE34 | B36: =VLOOKUP(Table6[[#This Row],[Customer_ID]],Table1[[Customer_ID]:[Name]],2,FALSE) -> Evelyn Brown | C36: =VLOOKUP(Table6[[#This Row],[Customer_ID]],Table1[[Customer_ID]:[City]],5,FALSE) -> West Victoriaborough | D36: =VLOOKUP(Table6[[#This Row],[Customer_ID]],Table1[],3,FALSE) -> 39 | E36: =VLOOKUP(Table6[[#This Row],[Customer_ID]],Table1[],4,FALSE) -> Male | F36: =VLOOKUP(Table6[[#This Row],[Customer_ID]],Table1[],6,FALSE) -> New Mexico | G36: =VLOOKUP(Table6[[#This Row],[Customer_ID]],Table1[],8,FALSE) -> Gold | H36: CUST1344 | I36: 45215 | J36: PROD79 | K36: =VLOOKUP($J36,'Product_Dim (2)'!$A$2:$G$101,{3,4,5,6},FALSE) -> Home | L36: =VLOOKUP($J36,'Product_Dim (2)'!$A$2:$G$101,{4,5,6},FALSE) -> Lighting | M36: {=VLOOKUP($J36,'Product_Dim (2)'!$A$2:$G$101,{6},FALSE)} -> 228.53 | N36: =VLOOKUP($J36,'Product_Dim (2)'!$A$2:$G$101,7,FALSE) -> 469 | O36: STORE1 | P36: =VLOOKUP($O36,'Store_Dim (2)'!$A$2:$E$21,2,FALSE) -> Martinez, Adkins and Johnson | Q36: =VLOOKUP(Table6[[#This Row],[Store_ID]],Table4[],3,FALSE) -> North | R36: =VLOOKUP(Table6[[#This Row],[Store_ID]],Table4[],4,FALSE) -> Danielmouth | S36: =VLOOKUP(Table6[[#This Row],[Store_ID]],Table4[],5,FALSE) -> Flagship | T36: =X36/(U36*(1-V36)) -> 3 | U36: 873.22 | V36: 0.18 | W36: Credit Card | X36: 2148.1212
A37: SALE35 | B37: =VLOOKUP(Table6[[#This Row],[Customer_ID]],Table1[[Customer_ID]:[Name]],2,FALSE) -> Julia Jackson | C37: =VLOOKUP(Table6[[#This Row],[Customer_ID]],Table1[[Customer_ID]:[City]],5,FALSE) -> Edwardland | D37: =VLOOKUP(Table6[[#This Row],[Customer_ID]],Table1[],3,FALSE) -> 46 | E37: =VLOOKUP(Table6[[#This Row],[Customer_ID]],Table1[],4,FALSE) -> Male | F37: =VLOOKUP(Table6[[#This Row],[Customer_ID]],Table1[],6,FALSE) -> California | G37: =VLOOKUP(Table6[[#This Row],[Customer_ID]],Table1[],8,FALSE) -> Platinum | H37: CUST1218 | I37: 45878 | J37: PROD16 | K37: =VLOOKUP($J37,'Product_Dim (2)'!$A$2:$G$101,{3,4,5,6},FALSE) -> Beauty | L37: =VLOOKUP($J37,'Product_Dim (2)'!$A$2:$G$101,{4,5,6},FALSE) -> Grooming | M37: {=VLOOKUP($J37,'Product_Dim (2)'!$A$2:$G$101,{6},FALSE)} -> 337.42 | N37: =VLOOKUP($J37,'Product_Dim (2)'!$A$2:$G$101,7,FALSE) -> 256 | O37: STORE3 | P37: =VLOOKUP($O37,'Store_Dim (2)'!$A$2:$E$21,2,FALSE) -> Johnson-Wright | Q37: =VLOOKUP(Table6[[#This Row],[Store_ID]],Table4[],3,FALSE) -> North | R37: =VLOOKUP(Table6[[#This Row],[Store_ID]],Table4[],4,FALSE) -> Hoodberg | S37: =VLOOKUP(Table6[[#This Row],[Store_ID]],Table4[],5,FALSE) -> Outlet | T37: 4 | U37: 109.36 | V37: 0.19 | W37: COD | X37: 354.3264
A38: SALE36 | B38: =VLOOKUP(Table6[[#This Row],[Customer_ID]],Table1[[Customer_ID]:[Name]],2,FALSE) -> Tammy Miller Md | C38: =VLOOKUP(Table6[[#This Row],[Customer_ID]],Table1[[Customer_ID]:[City]],5,FALSE) -> Austinfurt | D38: =VLOOKUP(Table6[[#This Row],[Customer_ID]],Table1[],3,FALSE) -> 19 | E38: =VLOOKUP(Table6[[#This Row],[Customer_ID]],Table1[],4,FALSE) -> Female | F38: =VLOOKUP(Table6[[#This Row],[Customer_ID]],Table1[],6,FALSE) -> Mississippi | G38: =VLOOKUP(Table6[[#This Row],[Customer_ID]],Table1[],8,FALSE) -> Gold | H38: CUST1086 | I38: 45635 | J38: PROD5 | K38: =VLOOKUP($J38,'Product_Dim (2)'!$A$2:$G$101,{3,4,5,6},FALSE) -> Clothing | L38: =VLOOKUP($J38,'Product_Dim (2)'!$A$2:$G$101,{4,5,6},FALSE) -> Accessories | M38: {=VLOOKUP($J38,'Product_Dim (2)'!$A$2:$G$101,{6},FALSE)} -> 261 | N38: =VLOOKUP($J38,'Product_Dim (2)'!$A$2:$G$101,7,FALSE) -> 59 | O38: STORE7 | P38: =VLOOKUP($O38,'Store_Dim (2)'!$A$2:$E$21,2,FALSE) -> Martinez-Mullins | Q38: =VLOOKUP(Table6[[#This Row],[Store_ID]],Table4[],3,FALSE) -> South | R38: =VLOOKUP(Table6[[#This Row],[Store_ID]],Table4[],4,FALSE) -> Williamsfurt | S38: =VLOOKUP(Table6[[#This Row],[Store_ID]],Table4[],5,FALSE) -> Online | T38: 3 | U38: 559.52 | V38: 0.16 | W38: PayPal | X38: 1409.9904
A39: SALE37 | B39: =VLOOKUP(Table6[[#This Row],[Customer_ID]],Table1[[Customer_ID]:[Name]],2,FALSE) -> Darrell Miller | C39: =VLOOKUP(Table6[[#This Row],[Customer_ID]],Table1[[Customer_ID]:[City]],5,FALSE) -> Port Carol | D39: =VLOOKUP(Table6[[#This Row],[Customer_ID]],Table1[],3,FALSE) -> 59 | E39: =VLOOKUP(Table6[[#This Row],[Customer_ID]],Table1[],4,FALSE) -> Female | F39: =VLOOKUP(Table6[[#This Row],[Customer_ID]],Table1[],6,FALSE) -> Florida | G39: =VLOOKUP(Table6[[#This Row],[Customer_ID]],Table1[],8,FALSE) -> Platinum | H39: CUST1492 | I39: 45329 | J39: PROD10 | K39: =VLOOKUP($J39,'Product_Dim (2)'!$A$2:$G$101,{3,4,5,6},FALSE) -> Home | L39: =VLOOKUP($J39,'Product_Dim (2)'!$A$2:$G$101,{4,5,6},FALSE) -> Kitchen | M39: {=VLOOKUP($J39,'Product_Dim (2)'!$A$2:$G$101,{6},FALSE)} -> 298.86 | N39: =VLOOKUP($J39,'Product_Dim (2)'!$A$2:$G$101,7,FALSE) -> 308 | O39: STORE17 | P39: =VLOOKUP($O39,'Store_Dim (2)'!$A$2:$E$21,2,FALSE) -> Holloway Ltd | Q39: =VLOOKUP(Table6[[#This Row],[Store_ID]],Table4[],3,FALSE) -> North | R39: =VLOOKUP(Table6[[#This Row],[Store_ID]],Table4[],4,FALSE) -> Bensonhaven | S39: =VLOOKUP(Table6[[#This Row],[Store_ID]],Table4[],5,FALSE) -> Flagship | T39: 3 | U39: 121.76 | V39: 0.27 | W39: PayPal | X39: 266.6544
A40: SALE38 | B40: =VLOOKUP(Table6[[#This Row],[Customer_ID]],Table1[[Customer_ID]:[Name]],2,FALSE) -> Daniel Austin | C40: =VLOOKUP(Table6[[#This Row],[Customer_ID]],Table1[[Customer_ID]:[City]],5,FALSE) -> Lake Howardberg | D40: =VLOOKUP(Table6[[#This Row],[Customer_ID]],Table1[],3,FALSE) -> 29 | E40: =VLOOKUP(Table6[[#This Row],[Customer_ID]],Table1[],4,FALSE) -> Male | F40: =VLOOKUP(Table6[[#This Row],[Customer_ID]],Table1[],6,FALSE) -> Kentucky | G40: =VLOOKUP(Table6[[#This Row],[Customer_ID]],Table1[],8,FALSE) -> Gold | H40: CUST1189 | I40: 45378 | J40: PROD33 | K40: =VLOOKUP($J40,'Product_Dim (2)'!$A$2:$G$101,{3,4,5,6},FALSE) -> Home | L40: =VLOOKUP($J40,'Product_Dim (2)'!$A$2:$G$101,{4,5,6},FALSE) -> Decor | M40: {=VLOOKUP($J40,'Product_Dim (2)'!$A$2:$G$101,{6},FALSE)} -> 179.77 | N40: =VLOOKUP($J40,'Product_Dim (2)'!$A$2:$G$101,7,FALSE) -> 305 | O40: STORE13 | P40: =VLOOKUP($O40,'Store_Dim (2)'!$A$2:$E$21,2,FALSE) -> Gardner, Humphrey and Contreras | Q40: =VLOOKUP(Table6[[#This Row],[Store_ID]],Table4[],3,FALSE) -> East | R40: =VLOOKUP(Table6[[#This Row],[Store_ID]],Table4[],4,FALSE) -> Johnsonville | S40: =VLOOKUP(Table6[[#This Row],[Store_ID]],Table4[],5,FALSE) -> Flagship | T40: 4 | U40: 735.32 | V40: 0.06 | W40: COD | X40: 2764.8032
...

Sheet Aggregrate functions
B4: Total number of transactions | G4: =COUNTA(Table6[Sales_ID]) -> 2000
B5: Total revenue generated | G5: =SUM(Table6[Total_Amount]) -> 2174394.7
B6: Average revenue per transaction | G6: =AVERAGE(Table6[Total_Amount]) -> 1087.1973
B7: Average quantity of products sold per transaction | G7: =INT(AVERAGE(Table6[Quantity])) -> 2
B8: Average discount percentage | G8: =AVERAGE(Table6[Discount]) -> 0.14796
B9: Loyalty | G9: =INDEX(Table6[Loyalty_level],_xlfn.MODE.MULT(MATCH(Table6[Loyalty_level],Table6[Loyalty_level],FALSE))) -> Platinum
B10: Total revenue from Male customers | G10: =SUMIF(Table6[Sex],"Male",Table6[Total_Amount]) -> 942950.47
B11: Total revenue from Female customers | G11: =SUMIF(Table6[Sex],"Female",Table6[Total_Amount]) -> 1231444.2
B12: Number of purchases by female customers | G12: =COUNTIF(Table6[Sex],"Female") -> 1096
B13: Number of purchases by male customers | G13: =COUNTIF(Table6[Sex],"Male") -> 904
B14: Total revenue generated from location | D14: Indiana | G14: =SUMIF(Table6[State],"Indiana",Table6[Total_Amount]) -> 51827.029
B15: Most popular popular category | G15: =INDEX(Table6[Category],_xlfn.MODE.MULT(MATCH(Table6[Category],Table6[Category],0))) -> Sports
B16: Location with the Most customers | G16: =INDEX(Table6[City],_xlfn.MODE.MULT(MATCH(Table6[City],Table6[City],0))) -> Christopherland
B17: Total quantity | G17: =SUM(Table6[Quantity]) -> 4964

Sheet Analysis ToolPak
E6: Quantity | I6: Total_Amount | M6: Discount
E8: Mean | F8: 2.482 | I8: Mean | J8: 1087.1973 | M8: Mean | N8: 0.14796
E9: Standard Error | F9: 0.024852501 | I9: Standard Error | J9: 18.327237 | M9: Standard Error | N9: 0.0019598571
E10: Median | F10: 2 | I10: Median | J10: 868.7182 | M10: Median | N10: 0.14
E11: Mode | F11: 2 | I11: Mode | J11: #N/A | M11: Mode | N11: 0.1
E12: Standard Deviation | F12: 1.1114376 | I12: Standard Deviation | J12: 819.61896 | M12: Standard Deviation | N12: 0.087647473
E13: Sample Variance | F13: 1.2352936 | I13: Sample Variance | J13: 671775.25 | M13: Sample Variance | N13: 0.0076820794
